{
 "cells": [
  {
   "cell_type": "code",
   "execution_count": 18,
   "metadata": {},
   "outputs": [
    {
     "data": {
      "text/plain": [
       "<queue.Queue at 0x21e7a60ee20>"
      ]
     },
     "execution_count": 18,
     "metadata": {},
     "output_type": "execute_result"
    },
    {
     "name": "stderr",
     "output_type": "stream",
     "text": [
      "Error while getting Updates: Conflict: terminated by other getUpdates request; make sure that only one bot instance is running\n",
      "No error handlers are registered, logging exception.\n",
      "Traceback (most recent call last):\n",
      "  File \"C:\\Users\\ANTHONY\\anaconda3\\lib\\site-packages\\telegram\\ext\\updater.py\", line 520, in _network_loop_retry\n",
      "    if not action_cb():\n",
      "  File \"C:\\Users\\ANTHONY\\anaconda3\\lib\\site-packages\\telegram\\ext\\updater.py\", line 471, in polling_action_cb\n",
      "    updates = self.bot.get_updates(\n",
      "  File \"C:\\Users\\ANTHONY\\anaconda3\\lib\\site-packages\\telegram\\bot.py\", line 127, in decorator\n",
      "    result = func(*args, **kwargs)\n",
      "  File \"C:\\Users\\ANTHONY\\anaconda3\\lib\\site-packages\\telegram\\bot.py\", line 2761, in get_updates\n",
      "    result = self._post(\n",
      "  File \"C:\\Users\\ANTHONY\\anaconda3\\lib\\site-packages\\telegram\\bot.py\", line 259, in _post\n",
      "    return self.request.post(\n",
      "  File \"C:\\Users\\ANTHONY\\anaconda3\\lib\\site-packages\\telegram\\utils\\request.py\", line 350, in post\n",
      "    result = self._request_wrapper(\n",
      "  File \"C:\\Users\\ANTHONY\\anaconda3\\lib\\site-packages\\telegram\\utils\\request.py\", line 277, in _request_wrapper\n",
      "    raise Conflict(message)\n",
      "telegram.error.Conflict: Conflict: terminated by other getUpdates request; make sure that only one bot instance is running\n",
      "Error while getting Updates: Conflict: terminated by other getUpdates request; make sure that only one bot instance is running\n",
      "No error handlers are registered, logging exception.\n",
      "Traceback (most recent call last):\n",
      "  File \"C:\\Users\\ANTHONY\\anaconda3\\lib\\site-packages\\telegram\\ext\\updater.py\", line 520, in _network_loop_retry\n",
      "    if not action_cb():\n",
      "  File \"C:\\Users\\ANTHONY\\anaconda3\\lib\\site-packages\\telegram\\ext\\updater.py\", line 471, in polling_action_cb\n",
      "    updates = self.bot.get_updates(\n",
      "  File \"C:\\Users\\ANTHONY\\anaconda3\\lib\\site-packages\\telegram\\bot.py\", line 127, in decorator\n",
      "    result = func(*args, **kwargs)\n",
      "  File \"C:\\Users\\ANTHONY\\anaconda3\\lib\\site-packages\\telegram\\bot.py\", line 2761, in get_updates\n",
      "    result = self._post(\n",
      "  File \"C:\\Users\\ANTHONY\\anaconda3\\lib\\site-packages\\telegram\\bot.py\", line 259, in _post\n",
      "    return self.request.post(\n",
      "  File \"C:\\Users\\ANTHONY\\anaconda3\\lib\\site-packages\\telegram\\utils\\request.py\", line 350, in post\n",
      "    result = self._request_wrapper(\n",
      "  File \"C:\\Users\\ANTHONY\\anaconda3\\lib\\site-packages\\telegram\\utils\\request.py\", line 277, in _request_wrapper\n",
      "    raise Conflict(message)\n",
      "telegram.error.Conflict: Conflict: terminated by other getUpdates request; make sure that only one bot instance is running\n",
      "Error while getting Updates: Conflict: terminated by other getUpdates request; make sure that only one bot instance is running\n",
      "No error handlers are registered, logging exception.\n",
      "Traceback (most recent call last):\n",
      "  File \"C:\\Users\\ANTHONY\\anaconda3\\lib\\site-packages\\telegram\\ext\\updater.py\", line 520, in _network_loop_retry\n",
      "    if not action_cb():\n",
      "  File \"C:\\Users\\ANTHONY\\anaconda3\\lib\\site-packages\\telegram\\ext\\updater.py\", line 471, in polling_action_cb\n",
      "    updates = self.bot.get_updates(\n",
      "  File \"C:\\Users\\ANTHONY\\anaconda3\\lib\\site-packages\\telegram\\bot.py\", line 127, in decorator\n",
      "    result = func(*args, **kwargs)\n",
      "  File \"C:\\Users\\ANTHONY\\anaconda3\\lib\\site-packages\\telegram\\bot.py\", line 2761, in get_updates\n",
      "    result = self._post(\n",
      "  File \"C:\\Users\\ANTHONY\\anaconda3\\lib\\site-packages\\telegram\\bot.py\", line 259, in _post\n",
      "    return self.request.post(\n",
      "  File \"C:\\Users\\ANTHONY\\anaconda3\\lib\\site-packages\\telegram\\utils\\request.py\", line 350, in post\n",
      "    result = self._request_wrapper(\n",
      "  File \"C:\\Users\\ANTHONY\\anaconda3\\lib\\site-packages\\telegram\\utils\\request.py\", line 277, in _request_wrapper\n",
      "    raise Conflict(message)\n",
      "telegram.error.Conflict: Conflict: terminated by other getUpdates request; make sure that only one bot instance is running\n",
      "Error while getting Updates: Conflict: terminated by other getUpdates request; make sure that only one bot instance is running\n",
      "No error handlers are registered, logging exception.\n",
      "Traceback (most recent call last):\n",
      "  File \"C:\\Users\\ANTHONY\\anaconda3\\lib\\site-packages\\telegram\\ext\\updater.py\", line 520, in _network_loop_retry\n",
      "    if not action_cb():\n",
      "  File \"C:\\Users\\ANTHONY\\anaconda3\\lib\\site-packages\\telegram\\ext\\updater.py\", line 471, in polling_action_cb\n",
      "    updates = self.bot.get_updates(\n",
      "  File \"C:\\Users\\ANTHONY\\anaconda3\\lib\\site-packages\\telegram\\bot.py\", line 127, in decorator\n",
      "    result = func(*args, **kwargs)\n",
      "  File \"C:\\Users\\ANTHONY\\anaconda3\\lib\\site-packages\\telegram\\bot.py\", line 2761, in get_updates\n",
      "    result = self._post(\n",
      "  File \"C:\\Users\\ANTHONY\\anaconda3\\lib\\site-packages\\telegram\\bot.py\", line 259, in _post\n",
      "    return self.request.post(\n",
      "  File \"C:\\Users\\ANTHONY\\anaconda3\\lib\\site-packages\\telegram\\utils\\request.py\", line 350, in post\n",
      "    result = self._request_wrapper(\n",
      "  File \"C:\\Users\\ANTHONY\\anaconda3\\lib\\site-packages\\telegram\\utils\\request.py\", line 277, in _request_wrapper\n",
      "    raise Conflict(message)\n",
      "telegram.error.Conflict: Conflict: terminated by other getUpdates request; make sure that only one bot instance is running\n",
      "Error while getting Updates: Conflict: terminated by other getUpdates request; make sure that only one bot instance is running\n",
      "No error handlers are registered, logging exception.\n",
      "Traceback (most recent call last):\n",
      "  File \"C:\\Users\\ANTHONY\\anaconda3\\lib\\site-packages\\telegram\\ext\\updater.py\", line 520, in _network_loop_retry\n",
      "    if not action_cb():\n",
      "  File \"C:\\Users\\ANTHONY\\anaconda3\\lib\\site-packages\\telegram\\ext\\updater.py\", line 471, in polling_action_cb\n",
      "    updates = self.bot.get_updates(\n",
      "  File \"C:\\Users\\ANTHONY\\anaconda3\\lib\\site-packages\\telegram\\bot.py\", line 127, in decorator\n",
      "    result = func(*args, **kwargs)\n",
      "  File \"C:\\Users\\ANTHONY\\anaconda3\\lib\\site-packages\\telegram\\bot.py\", line 2761, in get_updates\n",
      "    result = self._post(\n",
      "  File \"C:\\Users\\ANTHONY\\anaconda3\\lib\\site-packages\\telegram\\bot.py\", line 259, in _post\n",
      "    return self.request.post(\n",
      "  File \"C:\\Users\\ANTHONY\\anaconda3\\lib\\site-packages\\telegram\\utils\\request.py\", line 350, in post\n",
      "    result = self._request_wrapper(\n",
      "  File \"C:\\Users\\ANTHONY\\anaconda3\\lib\\site-packages\\telegram\\utils\\request.py\", line 277, in _request_wrapper\n",
      "    raise Conflict(message)\n",
      "telegram.error.Conflict: Conflict: terminated by other getUpdates request; make sure that only one bot instance is running\n",
      "Error while getting Updates: Conflict: terminated by other getUpdates request; make sure that only one bot instance is running\n",
      "No error handlers are registered, logging exception.\n",
      "Traceback (most recent call last):\n",
      "  File \"C:\\Users\\ANTHONY\\anaconda3\\lib\\site-packages\\telegram\\ext\\updater.py\", line 520, in _network_loop_retry\n",
      "    if not action_cb():\n",
      "  File \"C:\\Users\\ANTHONY\\anaconda3\\lib\\site-packages\\telegram\\ext\\updater.py\", line 471, in polling_action_cb\n",
      "    updates = self.bot.get_updates(\n",
      "  File \"C:\\Users\\ANTHONY\\anaconda3\\lib\\site-packages\\telegram\\bot.py\", line 127, in decorator\n",
      "    result = func(*args, **kwargs)\n",
      "  File \"C:\\Users\\ANTHONY\\anaconda3\\lib\\site-packages\\telegram\\bot.py\", line 2761, in get_updates\n",
      "    result = self._post(\n",
      "  File \"C:\\Users\\ANTHONY\\anaconda3\\lib\\site-packages\\telegram\\bot.py\", line 259, in _post\n",
      "    return self.request.post(\n",
      "  File \"C:\\Users\\ANTHONY\\anaconda3\\lib\\site-packages\\telegram\\utils\\request.py\", line 350, in post\n",
      "    result = self._request_wrapper(\n",
      "  File \"C:\\Users\\ANTHONY\\anaconda3\\lib\\site-packages\\telegram\\utils\\request.py\", line 277, in _request_wrapper\n",
      "    raise Conflict(message)\n",
      "telegram.error.Conflict: Conflict: terminated by other getUpdates request; make sure that only one bot instance is running\n",
      "Error while getting Updates: Conflict: terminated by other getUpdates request; make sure that only one bot instance is running\n",
      "No error handlers are registered, logging exception.\n",
      "Traceback (most recent call last):\n",
      "  File \"C:\\Users\\ANTHONY\\anaconda3\\lib\\site-packages\\telegram\\ext\\updater.py\", line 520, in _network_loop_retry\n",
      "    if not action_cb():\n",
      "  File \"C:\\Users\\ANTHONY\\anaconda3\\lib\\site-packages\\telegram\\ext\\updater.py\", line 471, in polling_action_cb\n",
      "    updates = self.bot.get_updates(\n",
      "  File \"C:\\Users\\ANTHONY\\anaconda3\\lib\\site-packages\\telegram\\bot.py\", line 127, in decorator\n",
      "    result = func(*args, **kwargs)\n",
      "  File \"C:\\Users\\ANTHONY\\anaconda3\\lib\\site-packages\\telegram\\bot.py\", line 2761, in get_updates\n",
      "    result = self._post(\n",
      "  File \"C:\\Users\\ANTHONY\\anaconda3\\lib\\site-packages\\telegram\\bot.py\", line 259, in _post\n",
      "    return self.request.post(\n",
      "  File \"C:\\Users\\ANTHONY\\anaconda3\\lib\\site-packages\\telegram\\utils\\request.py\", line 350, in post\n",
      "    result = self._request_wrapper(\n",
      "  File \"C:\\Users\\ANTHONY\\anaconda3\\lib\\site-packages\\telegram\\utils\\request.py\", line 277, in _request_wrapper\n",
      "    raise Conflict(message)\n",
      "telegram.error.Conflict: Conflict: terminated by other getUpdates request; make sure that only one bot instance is running\n"
     ]
    },
    {
     "name": "stderr",
     "output_type": "stream",
     "text": [
      "Error while getting Updates: Conflict: terminated by other getUpdates request; make sure that only one bot instance is running\n",
      "No error handlers are registered, logging exception.\n",
      "Traceback (most recent call last):\n",
      "  File \"C:\\Users\\ANTHONY\\anaconda3\\lib\\site-packages\\telegram\\ext\\updater.py\", line 520, in _network_loop_retry\n",
      "    if not action_cb():\n",
      "  File \"C:\\Users\\ANTHONY\\anaconda3\\lib\\site-packages\\telegram\\ext\\updater.py\", line 471, in polling_action_cb\n",
      "    updates = self.bot.get_updates(\n",
      "  File \"C:\\Users\\ANTHONY\\anaconda3\\lib\\site-packages\\telegram\\bot.py\", line 127, in decorator\n",
      "    result = func(*args, **kwargs)\n",
      "  File \"C:\\Users\\ANTHONY\\anaconda3\\lib\\site-packages\\telegram\\bot.py\", line 2761, in get_updates\n",
      "    result = self._post(\n",
      "  File \"C:\\Users\\ANTHONY\\anaconda3\\lib\\site-packages\\telegram\\bot.py\", line 259, in _post\n",
      "    return self.request.post(\n",
      "  File \"C:\\Users\\ANTHONY\\anaconda3\\lib\\site-packages\\telegram\\utils\\request.py\", line 350, in post\n",
      "    result = self._request_wrapper(\n",
      "  File \"C:\\Users\\ANTHONY\\anaconda3\\lib\\site-packages\\telegram\\utils\\request.py\", line 277, in _request_wrapper\n",
      "    raise Conflict(message)\n",
      "telegram.error.Conflict: Conflict: terminated by other getUpdates request; make sure that only one bot instance is running\n",
      "Error while getting Updates: Conflict: terminated by other getUpdates request; make sure that only one bot instance is running\n",
      "No error handlers are registered, logging exception.\n",
      "Traceback (most recent call last):\n",
      "  File \"C:\\Users\\ANTHONY\\anaconda3\\lib\\site-packages\\telegram\\ext\\updater.py\", line 520, in _network_loop_retry\n",
      "    if not action_cb():\n",
      "  File \"C:\\Users\\ANTHONY\\anaconda3\\lib\\site-packages\\telegram\\ext\\updater.py\", line 471, in polling_action_cb\n",
      "    updates = self.bot.get_updates(\n",
      "  File \"C:\\Users\\ANTHONY\\anaconda3\\lib\\site-packages\\telegram\\bot.py\", line 127, in decorator\n",
      "    result = func(*args, **kwargs)\n",
      "  File \"C:\\Users\\ANTHONY\\anaconda3\\lib\\site-packages\\telegram\\bot.py\", line 2761, in get_updates\n",
      "    result = self._post(\n",
      "  File \"C:\\Users\\ANTHONY\\anaconda3\\lib\\site-packages\\telegram\\bot.py\", line 259, in _post\n",
      "    return self.request.post(\n",
      "  File \"C:\\Users\\ANTHONY\\anaconda3\\lib\\site-packages\\telegram\\utils\\request.py\", line 350, in post\n",
      "    result = self._request_wrapper(\n",
      "  File \"C:\\Users\\ANTHONY\\anaconda3\\lib\\site-packages\\telegram\\utils\\request.py\", line 277, in _request_wrapper\n",
      "    raise Conflict(message)\n",
      "telegram.error.Conflict: Conflict: terminated by other getUpdates request; make sure that only one bot instance is running\n",
      "Error while getting Updates: Conflict: terminated by other getUpdates request; make sure that only one bot instance is running\n",
      "No error handlers are registered, logging exception.\n",
      "Traceback (most recent call last):\n",
      "  File \"C:\\Users\\ANTHONY\\anaconda3\\lib\\site-packages\\telegram\\ext\\updater.py\", line 520, in _network_loop_retry\n",
      "    if not action_cb():\n",
      "  File \"C:\\Users\\ANTHONY\\anaconda3\\lib\\site-packages\\telegram\\ext\\updater.py\", line 471, in polling_action_cb\n",
      "    updates = self.bot.get_updates(\n",
      "  File \"C:\\Users\\ANTHONY\\anaconda3\\lib\\site-packages\\telegram\\bot.py\", line 127, in decorator\n",
      "    result = func(*args, **kwargs)\n",
      "  File \"C:\\Users\\ANTHONY\\anaconda3\\lib\\site-packages\\telegram\\bot.py\", line 2761, in get_updates\n",
      "    result = self._post(\n",
      "  File \"C:\\Users\\ANTHONY\\anaconda3\\lib\\site-packages\\telegram\\bot.py\", line 259, in _post\n",
      "    return self.request.post(\n",
      "  File \"C:\\Users\\ANTHONY\\anaconda3\\lib\\site-packages\\telegram\\utils\\request.py\", line 350, in post\n",
      "    result = self._request_wrapper(\n",
      "  File \"C:\\Users\\ANTHONY\\anaconda3\\lib\\site-packages\\telegram\\utils\\request.py\", line 277, in _request_wrapper\n",
      "    raise Conflict(message)\n",
      "telegram.error.Conflict: Conflict: terminated by other getUpdates request; make sure that only one bot instance is running\n",
      "Error while getting Updates: Conflict: terminated by other getUpdates request; make sure that only one bot instance is running\n",
      "No error handlers are registered, logging exception.\n",
      "Traceback (most recent call last):\n",
      "  File \"C:\\Users\\ANTHONY\\anaconda3\\lib\\site-packages\\telegram\\ext\\updater.py\", line 520, in _network_loop_retry\n",
      "    if not action_cb():\n",
      "  File \"C:\\Users\\ANTHONY\\anaconda3\\lib\\site-packages\\telegram\\ext\\updater.py\", line 471, in polling_action_cb\n",
      "    updates = self.bot.get_updates(\n",
      "  File \"C:\\Users\\ANTHONY\\anaconda3\\lib\\site-packages\\telegram\\bot.py\", line 127, in decorator\n",
      "    result = func(*args, **kwargs)\n",
      "  File \"C:\\Users\\ANTHONY\\anaconda3\\lib\\site-packages\\telegram\\bot.py\", line 2761, in get_updates\n",
      "    result = self._post(\n",
      "  File \"C:\\Users\\ANTHONY\\anaconda3\\lib\\site-packages\\telegram\\bot.py\", line 259, in _post\n",
      "    return self.request.post(\n",
      "  File \"C:\\Users\\ANTHONY\\anaconda3\\lib\\site-packages\\telegram\\utils\\request.py\", line 350, in post\n",
      "    result = self._request_wrapper(\n",
      "  File \"C:\\Users\\ANTHONY\\anaconda3\\lib\\site-packages\\telegram\\utils\\request.py\", line 277, in _request_wrapper\n",
      "    raise Conflict(message)\n",
      "telegram.error.Conflict: Conflict: terminated by other getUpdates request; make sure that only one bot instance is running\n",
      "Error while getting Updates: Conflict: terminated by other getUpdates request; make sure that only one bot instance is running\n",
      "No error handlers are registered, logging exception.\n",
      "Traceback (most recent call last):\n",
      "  File \"C:\\Users\\ANTHONY\\anaconda3\\lib\\site-packages\\telegram\\ext\\updater.py\", line 520, in _network_loop_retry\n",
      "    if not action_cb():\n",
      "  File \"C:\\Users\\ANTHONY\\anaconda3\\lib\\site-packages\\telegram\\ext\\updater.py\", line 471, in polling_action_cb\n",
      "    updates = self.bot.get_updates(\n",
      "  File \"C:\\Users\\ANTHONY\\anaconda3\\lib\\site-packages\\telegram\\bot.py\", line 127, in decorator\n",
      "    result = func(*args, **kwargs)\n",
      "  File \"C:\\Users\\ANTHONY\\anaconda3\\lib\\site-packages\\telegram\\bot.py\", line 2761, in get_updates\n",
      "    result = self._post(\n",
      "  File \"C:\\Users\\ANTHONY\\anaconda3\\lib\\site-packages\\telegram\\bot.py\", line 259, in _post\n",
      "    return self.request.post(\n",
      "  File \"C:\\Users\\ANTHONY\\anaconda3\\lib\\site-packages\\telegram\\utils\\request.py\", line 350, in post\n",
      "    result = self._request_wrapper(\n",
      "  File \"C:\\Users\\ANTHONY\\anaconda3\\lib\\site-packages\\telegram\\utils\\request.py\", line 277, in _request_wrapper\n",
      "    raise Conflict(message)\n",
      "telegram.error.Conflict: Conflict: terminated by other getUpdates request; make sure that only one bot instance is running\n",
      "Error while getting Updates: Conflict: terminated by other getUpdates request; make sure that only one bot instance is running\n",
      "No error handlers are registered, logging exception.\n",
      "Traceback (most recent call last):\n",
      "  File \"C:\\Users\\ANTHONY\\anaconda3\\lib\\site-packages\\telegram\\ext\\updater.py\", line 520, in _network_loop_retry\n",
      "    if not action_cb():\n",
      "  File \"C:\\Users\\ANTHONY\\anaconda3\\lib\\site-packages\\telegram\\ext\\updater.py\", line 471, in polling_action_cb\n",
      "    updates = self.bot.get_updates(\n",
      "  File \"C:\\Users\\ANTHONY\\anaconda3\\lib\\site-packages\\telegram\\bot.py\", line 127, in decorator\n",
      "    result = func(*args, **kwargs)\n",
      "  File \"C:\\Users\\ANTHONY\\anaconda3\\lib\\site-packages\\telegram\\bot.py\", line 2761, in get_updates\n",
      "    result = self._post(\n",
      "  File \"C:\\Users\\ANTHONY\\anaconda3\\lib\\site-packages\\telegram\\bot.py\", line 259, in _post\n",
      "    return self.request.post(\n",
      "  File \"C:\\Users\\ANTHONY\\anaconda3\\lib\\site-packages\\telegram\\utils\\request.py\", line 350, in post\n",
      "    result = self._request_wrapper(\n",
      "  File \"C:\\Users\\ANTHONY\\anaconda3\\lib\\site-packages\\telegram\\utils\\request.py\", line 277, in _request_wrapper\n",
      "    raise Conflict(message)\n",
      "telegram.error.Conflict: Conflict: terminated by other getUpdates request; make sure that only one bot instance is running\n",
      "Error while getting Updates: Conflict: terminated by other getUpdates request; make sure that only one bot instance is running\n",
      "No error handlers are registered, logging exception.\n",
      "Traceback (most recent call last):\n",
      "  File \"C:\\Users\\ANTHONY\\anaconda3\\lib\\site-packages\\telegram\\ext\\updater.py\", line 520, in _network_loop_retry\n",
      "    if not action_cb():\n",
      "  File \"C:\\Users\\ANTHONY\\anaconda3\\lib\\site-packages\\telegram\\ext\\updater.py\", line 471, in polling_action_cb\n",
      "    updates = self.bot.get_updates(\n",
      "  File \"C:\\Users\\ANTHONY\\anaconda3\\lib\\site-packages\\telegram\\bot.py\", line 127, in decorator\n",
      "    result = func(*args, **kwargs)\n",
      "  File \"C:\\Users\\ANTHONY\\anaconda3\\lib\\site-packages\\telegram\\bot.py\", line 2761, in get_updates\n",
      "    result = self._post(\n",
      "  File \"C:\\Users\\ANTHONY\\anaconda3\\lib\\site-packages\\telegram\\bot.py\", line 259, in _post\n",
      "    return self.request.post(\n",
      "  File \"C:\\Users\\ANTHONY\\anaconda3\\lib\\site-packages\\telegram\\utils\\request.py\", line 350, in post\n",
      "    result = self._request_wrapper(\n",
      "  File \"C:\\Users\\ANTHONY\\anaconda3\\lib\\site-packages\\telegram\\utils\\request.py\", line 277, in _request_wrapper\n",
      "    raise Conflict(message)\n",
      "telegram.error.Conflict: Conflict: terminated by other getUpdates request; make sure that only one bot instance is running\n"
     ]
    }
   ],
   "source": [
    "from telegram.ext import *\n",
    "from telegram import *\n",
    "import requests\n",
    "import re\n",
    "\n",
    "\n",
    "\n",
    "def test_function(update:Update,context:CallbackContext):\n",
    "    bot.send_message(\n",
    "    chat_id=update.effective_chat.id,\n",
    "    text=\"PODA\")\n",
    "\n",
    "bot=Bot('1809540140:AAEND8ZbXvOEglMpP7YJoCR-U1ChyLq2dlc')\n",
    "updater = Updater('1809540140:AAEND8ZbXvOEglMpP7YJoCR-U1ChyLq2dlc',use_context=True)  ###  fro updating whatever is in the bot\n",
    "dp = updater.dispatcher   ##  dispatch the updates\n",
    "\n",
    "start_value=CommandHandler('Hello',test_function)\n",
    "dp.add_handler(start_value)   # update send using this dispatcher class\n",
    "\n",
    "updater.start_polling()\n",
    "\n",
    "#print(bot.get_me())\n"
   ]
  },
  {
   "cell_type": "code",
   "execution_count": null,
   "metadata": {},
   "outputs": [
    {
     "name": "stderr",
     "output_type": "stream",
     "text": [
      "Error while getting Updates: Conflict: terminated by other getUpdates request; make sure that only one bot instance is running\n",
      "No error handlers are registered, logging exception.\n",
      "Traceback (most recent call last):\n",
      "  File \"C:\\Users\\ANTHONY\\anaconda3\\lib\\site-packages\\telegram\\ext\\updater.py\", line 520, in _network_loop_retry\n",
      "    if not action_cb():\n",
      "  File \"C:\\Users\\ANTHONY\\anaconda3\\lib\\site-packages\\telegram\\ext\\updater.py\", line 471, in polling_action_cb\n",
      "    updates = self.bot.get_updates(\n",
      "  File \"C:\\Users\\ANTHONY\\anaconda3\\lib\\site-packages\\telegram\\bot.py\", line 127, in decorator\n",
      "    result = func(*args, **kwargs)\n",
      "  File \"C:\\Users\\ANTHONY\\anaconda3\\lib\\site-packages\\telegram\\bot.py\", line 2761, in get_updates\n",
      "    result = self._post(\n",
      "  File \"C:\\Users\\ANTHONY\\anaconda3\\lib\\site-packages\\telegram\\bot.py\", line 259, in _post\n",
      "    return self.request.post(\n",
      "  File \"C:\\Users\\ANTHONY\\anaconda3\\lib\\site-packages\\telegram\\utils\\request.py\", line 350, in post\n",
      "    result = self._request_wrapper(\n",
      "  File \"C:\\Users\\ANTHONY\\anaconda3\\lib\\site-packages\\telegram\\utils\\request.py\", line 277, in _request_wrapper\n",
      "    raise Conflict(message)\n",
      "telegram.error.Conflict: Conflict: terminated by other getUpdates request; make sure that only one bot instance is running\n",
      "Error while getting Updates: Conflict: terminated by other getUpdates request; make sure that only one bot instance is running\n",
      "No error handlers are registered, logging exception.\n",
      "Traceback (most recent call last):\n",
      "  File \"C:\\Users\\ANTHONY\\anaconda3\\lib\\site-packages\\telegram\\ext\\updater.py\", line 520, in _network_loop_retry\n",
      "    if not action_cb():\n",
      "  File \"C:\\Users\\ANTHONY\\anaconda3\\lib\\site-packages\\telegram\\ext\\updater.py\", line 471, in polling_action_cb\n",
      "    updates = self.bot.get_updates(\n",
      "  File \"C:\\Users\\ANTHONY\\anaconda3\\lib\\site-packages\\telegram\\bot.py\", line 127, in decorator\n",
      "    result = func(*args, **kwargs)\n",
      "  File \"C:\\Users\\ANTHONY\\anaconda3\\lib\\site-packages\\telegram\\bot.py\", line 2761, in get_updates\n",
      "    result = self._post(\n",
      "  File \"C:\\Users\\ANTHONY\\anaconda3\\lib\\site-packages\\telegram\\bot.py\", line 259, in _post\n",
      "    return self.request.post(\n",
      "  File \"C:\\Users\\ANTHONY\\anaconda3\\lib\\site-packages\\telegram\\utils\\request.py\", line 350, in post\n",
      "    result = self._request_wrapper(\n",
      "  File \"C:\\Users\\ANTHONY\\anaconda3\\lib\\site-packages\\telegram\\utils\\request.py\", line 277, in _request_wrapper\n",
      "    raise Conflict(message)\n",
      "telegram.error.Conflict: Conflict: terminated by other getUpdates request; make sure that only one bot instance is running\n",
      "Error while getting Updates: Conflict: terminated by other getUpdates request; make sure that only one bot instance is running\n",
      "No error handlers are registered, logging exception.\n",
      "Traceback (most recent call last):\n",
      "  File \"C:\\Users\\ANTHONY\\anaconda3\\lib\\site-packages\\telegram\\ext\\updater.py\", line 520, in _network_loop_retry\n",
      "    if not action_cb():\n",
      "  File \"C:\\Users\\ANTHONY\\anaconda3\\lib\\site-packages\\telegram\\ext\\updater.py\", line 471, in polling_action_cb\n",
      "    updates = self.bot.get_updates(\n",
      "  File \"C:\\Users\\ANTHONY\\anaconda3\\lib\\site-packages\\telegram\\bot.py\", line 127, in decorator\n",
      "    result = func(*args, **kwargs)\n",
      "  File \"C:\\Users\\ANTHONY\\anaconda3\\lib\\site-packages\\telegram\\bot.py\", line 2761, in get_updates\n",
      "    result = self._post(\n",
      "  File \"C:\\Users\\ANTHONY\\anaconda3\\lib\\site-packages\\telegram\\bot.py\", line 259, in _post\n",
      "    return self.request.post(\n",
      "  File \"C:\\Users\\ANTHONY\\anaconda3\\lib\\site-packages\\telegram\\utils\\request.py\", line 350, in post\n",
      "    result = self._request_wrapper(\n",
      "  File \"C:\\Users\\ANTHONY\\anaconda3\\lib\\site-packages\\telegram\\utils\\request.py\", line 277, in _request_wrapper\n",
      "    raise Conflict(message)\n",
      "telegram.error.Conflict: Conflict: terminated by other getUpdates request; make sure that only one bot instance is running\n",
      "Error while getting Updates: Conflict: terminated by other getUpdates request; make sure that only one bot instance is running\n",
      "No error handlers are registered, logging exception.\n",
      "Traceback (most recent call last):\n",
      "  File \"C:\\Users\\ANTHONY\\anaconda3\\lib\\site-packages\\telegram\\ext\\updater.py\", line 520, in _network_loop_retry\n",
      "    if not action_cb():\n",
      "  File \"C:\\Users\\ANTHONY\\anaconda3\\lib\\site-packages\\telegram\\ext\\updater.py\", line 471, in polling_action_cb\n",
      "    updates = self.bot.get_updates(\n",
      "  File \"C:\\Users\\ANTHONY\\anaconda3\\lib\\site-packages\\telegram\\bot.py\", line 127, in decorator\n",
      "    result = func(*args, **kwargs)\n",
      "  File \"C:\\Users\\ANTHONY\\anaconda3\\lib\\site-packages\\telegram\\bot.py\", line 2761, in get_updates\n",
      "    result = self._post(\n",
      "  File \"C:\\Users\\ANTHONY\\anaconda3\\lib\\site-packages\\telegram\\bot.py\", line 259, in _post\n",
      "    return self.request.post(\n",
      "  File \"C:\\Users\\ANTHONY\\anaconda3\\lib\\site-packages\\telegram\\utils\\request.py\", line 350, in post\n",
      "    result = self._request_wrapper(\n",
      "  File \"C:\\Users\\ANTHONY\\anaconda3\\lib\\site-packages\\telegram\\utils\\request.py\", line 277, in _request_wrapper\n",
      "    raise Conflict(message)\n",
      "telegram.error.Conflict: Conflict: terminated by other getUpdates request; make sure that only one bot instance is running\n",
      "Error while getting Updates: Conflict: terminated by other getUpdates request; make sure that only one bot instance is running\n",
      "No error handlers are registered, logging exception.\n",
      "Traceback (most recent call last):\n",
      "  File \"C:\\Users\\ANTHONY\\anaconda3\\lib\\site-packages\\telegram\\ext\\updater.py\", line 520, in _network_loop_retry\n",
      "    if not action_cb():\n",
      "  File \"C:\\Users\\ANTHONY\\anaconda3\\lib\\site-packages\\telegram\\ext\\updater.py\", line 471, in polling_action_cb\n",
      "    updates = self.bot.get_updates(\n",
      "  File \"C:\\Users\\ANTHONY\\anaconda3\\lib\\site-packages\\telegram\\bot.py\", line 127, in decorator\n",
      "    result = func(*args, **kwargs)\n",
      "  File \"C:\\Users\\ANTHONY\\anaconda3\\lib\\site-packages\\telegram\\bot.py\", line 2761, in get_updates\n",
      "    result = self._post(\n",
      "  File \"C:\\Users\\ANTHONY\\anaconda3\\lib\\site-packages\\telegram\\bot.py\", line 259, in _post\n",
      "    return self.request.post(\n",
      "  File \"C:\\Users\\ANTHONY\\anaconda3\\lib\\site-packages\\telegram\\utils\\request.py\", line 350, in post\n",
      "    result = self._request_wrapper(\n",
      "  File \"C:\\Users\\ANTHONY\\anaconda3\\lib\\site-packages\\telegram\\utils\\request.py\", line 277, in _request_wrapper\n",
      "    raise Conflict(message)\n",
      "telegram.error.Conflict: Conflict: terminated by other getUpdates request; make sure that only one bot instance is running\n",
      "Error while getting Updates: Conflict: terminated by other getUpdates request; make sure that only one bot instance is running\n",
      "No error handlers are registered, logging exception.\n",
      "Traceback (most recent call last):\n",
      "  File \"C:\\Users\\ANTHONY\\anaconda3\\lib\\site-packages\\telegram\\ext\\updater.py\", line 520, in _network_loop_retry\n",
      "    if not action_cb():\n",
      "  File \"C:\\Users\\ANTHONY\\anaconda3\\lib\\site-packages\\telegram\\ext\\updater.py\", line 471, in polling_action_cb\n",
      "    updates = self.bot.get_updates(\n",
      "  File \"C:\\Users\\ANTHONY\\anaconda3\\lib\\site-packages\\telegram\\bot.py\", line 127, in decorator\n",
      "    result = func(*args, **kwargs)\n",
      "  File \"C:\\Users\\ANTHONY\\anaconda3\\lib\\site-packages\\telegram\\bot.py\", line 2761, in get_updates\n",
      "    result = self._post(\n",
      "  File \"C:\\Users\\ANTHONY\\anaconda3\\lib\\site-packages\\telegram\\bot.py\", line 259, in _post\n",
      "    return self.request.post(\n",
      "  File \"C:\\Users\\ANTHONY\\anaconda3\\lib\\site-packages\\telegram\\utils\\request.py\", line 350, in post\n",
      "    result = self._request_wrapper(\n",
      "  File \"C:\\Users\\ANTHONY\\anaconda3\\lib\\site-packages\\telegram\\utils\\request.py\", line 277, in _request_wrapper\n",
      "    raise Conflict(message)\n",
      "telegram.error.Conflict: Conflict: terminated by other getUpdates request; make sure that only one bot instance is running\n",
      "Error while getting Updates: Conflict: terminated by other getUpdates request; make sure that only one bot instance is running\n",
      "No error handlers are registered, logging exception.\n",
      "Traceback (most recent call last):\n",
      "  File \"C:\\Users\\ANTHONY\\anaconda3\\lib\\site-packages\\telegram\\ext\\updater.py\", line 520, in _network_loop_retry\n",
      "    if not action_cb():\n",
      "  File \"C:\\Users\\ANTHONY\\anaconda3\\lib\\site-packages\\telegram\\ext\\updater.py\", line 471, in polling_action_cb\n",
      "    updates = self.bot.get_updates(\n",
      "  File \"C:\\Users\\ANTHONY\\anaconda3\\lib\\site-packages\\telegram\\bot.py\", line 127, in decorator\n",
      "    result = func(*args, **kwargs)\n",
      "  File \"C:\\Users\\ANTHONY\\anaconda3\\lib\\site-packages\\telegram\\bot.py\", line 2761, in get_updates\n",
      "    result = self._post(\n",
      "  File \"C:\\Users\\ANTHONY\\anaconda3\\lib\\site-packages\\telegram\\bot.py\", line 259, in _post\n",
      "    return self.request.post(\n",
      "  File \"C:\\Users\\ANTHONY\\anaconda3\\lib\\site-packages\\telegram\\utils\\request.py\", line 350, in post\n",
      "    result = self._request_wrapper(\n",
      "  File \"C:\\Users\\ANTHONY\\anaconda3\\lib\\site-packages\\telegram\\utils\\request.py\", line 277, in _request_wrapper\n",
      "    raise Conflict(message)\n",
      "telegram.error.Conflict: Conflict: terminated by other getUpdates request; make sure that only one bot instance is running\n"
     ]
    }
   ],
   "source": [
    "from telegram.ext import Updater, InlineQueryHandler, CommandHandler\n",
    "import requests\n",
    "import re\n",
    "\n",
    "def get_url():\n",
    "    contents = requests.get('https://random.dog/woof.json').json()    \n",
    "    url = contents['url']\n",
    "    return url\n",
    "\n",
    "def bop(bot, update):\n",
    "    url = get_url()\n",
    "    chat_id = update.message.chat_id\n",
    "    bot.send_photo(chat_id=chat_id, photo=url)\n",
    "\n",
    "def main():\n",
    "    updater = Updater('1875573222:AAGq07KDZYC0625XPwnK-12Oz1ZwD54W1rQ')\n",
    "    dp = updater.dispatcher\n",
    "    dp.add_handler(CommandHandler('Hii',bop))\n",
    "    updater.start_polling()\n",
    "    updater.idle()\n",
    "\n",
    "if __name__ == '__main__':\n",
    "    main()"
   ]
  },
  {
   "cell_type": "code",
   "execution_count": null,
   "metadata": {},
   "outputs": [],
   "source": [
    "import requests\n",
    "import json\n",
    "import configparser as cfg\n",
    "\n",
    "\n",
    "class telegram_chatbot():\n",
    "\n",
    "    def __init__(self, config):\n",
    "        self.token = self.read_token_from_config_file(config)\n",
    "        self.base = \"https://api.telegram.org/bot{}/\".format(self.token)\n",
    "\n",
    "    def get_updates(self, offset=None):\n",
    "        url = self.base + \"getUpdates?timeout=100\"\n",
    "        if offset:\n",
    "            url = url + \"&offset={}\".format(offset + 1)\n",
    "        r = requests.get(url)\n",
    "        return json.loads(r.content)\n",
    "\n",
    "    def send_message(self, msg, chat_id):\n",
    "        url = self.base + \"sendMessage?chat_id={}&text={}\".format(chat_id, msg)\n",
    "        if msg is not None:\n",
    "            requests.get(url)\n",
    "\n",
    "    def read_token_from_config_file(self, config):\n",
    "        parser = cfg.ConfigParser()\n",
    "        parser.read(config)\n",
    "        return parser.get('creds', 'token')"
   ]
  }
 ],
 "metadata": {
  "kernelspec": {
   "display_name": "Python 3",
   "language": "python",
   "name": "python3"
  },
  "language_info": {
   "codemirror_mode": {
    "name": "ipython",
    "version": 3
   },
   "file_extension": ".py",
   "mimetype": "text/x-python",
   "name": "python",
   "nbconvert_exporter": "python",
   "pygments_lexer": "ipython3",
   "version": "3.8.5"
  }
 },
 "nbformat": 4,
 "nbformat_minor": 4
}
